
Files already downloaded and verified
  0%|                                                                                                                                                                                                                                             | 0/200 [00:00<?, ?it/s]
Traceback (most recent call last):
  File "/home/developer/anaconda3/envs/pytorch/lib/python3.9/site-packages/urllib3/connection.py", line 174, in _new_conn
    conn = connection.create_connection(
  File "/home/developer/anaconda3/envs/pytorch/lib/python3.9/site-packages/urllib3/util/connection.py", line 95, in create_connection
    raise err
  File "/home/developer/anaconda3/envs/pytorch/lib/python3.9/site-packages/urllib3/util/connection.py", line 85, in create_connection
    sock.connect(sa)
ConnectionRefusedError: [Errno 111] Connection refused
During handling of the above exception, another exception occurred:
Traceback (most recent call last):
  File "/home/developer/anaconda3/envs/pytorch/lib/python3.9/site-packages/urllib3/connectionpool.py", line 703, in urlopen
    httplib_response = self._make_request(
  File "/home/developer/anaconda3/envs/pytorch/lib/python3.9/site-packages/urllib3/connectionpool.py", line 398, in _make_request
    conn.request(method, url, **httplib_request_kw)
  File "/home/developer/anaconda3/envs/pytorch/lib/python3.9/site-packages/urllib3/connection.py", line 244, in request
    super(HTTPConnection, self).request(method, url, body=body, headers=headers)
  File "/home/developer/anaconda3/envs/pytorch/lib/python3.9/http/client.py", line 1255, in request
    self._send_request(method, url, body, headers, encode_chunked)
  File "/home/developer/anaconda3/envs/pytorch/lib/python3.9/http/client.py", line 1301, in _send_request
    self.endheaders(body, encode_chunked=encode_chunked)
  File "/home/developer/anaconda3/envs/pytorch/lib/python3.9/http/client.py", line 1250, in endheaders
    self._send_output(message_body, encode_chunked=encode_chunked)
  File "/home/developer/anaconda3/envs/pytorch/lib/python3.9/http/client.py", line 1010, in _send_output
    self.send(msg)
  File "/home/developer/anaconda3/envs/pytorch/lib/python3.9/http/client.py", line 950, in send
    self.connect()
  File "/home/developer/anaconda3/envs/pytorch/lib/python3.9/site-packages/urllib3/connection.py", line 205, in connect
    conn = self._new_conn()
  File "/home/developer/anaconda3/envs/pytorch/lib/python3.9/site-packages/urllib3/connection.py", line 186, in _new_conn
    raise NewConnectionError(
urllib3.exceptions.NewConnectionError: <urllib3.connection.HTTPConnection object at 0x7fa7d6b58280>: Failed to establish a new connection: [Errno 111] Connection refused
During handling of the above exception, another exception occurred:
Traceback (most recent call last):
  File "/home/developer/anaconda3/envs/pytorch/lib/python3.9/site-packages/requests/adapters.py", line 489, in send
    resp = conn.urlopen(
  File "/home/developer/anaconda3/envs/pytorch/lib/python3.9/site-packages/urllib3/connectionpool.py", line 787, in urlopen
    retries = retries.increment(
  File "/home/developer/anaconda3/envs/pytorch/lib/python3.9/site-packages/urllib3/util/retry.py", line 592, in increment
    raise MaxRetryError(_pool, url, error or ResponseError(cause))
urllib3.exceptions.MaxRetryError: HTTPConnectionPool(host='127.0.0.1', port=8000): Max retries exceeded with url: /getStatus (Caused by NewConnectionError('<urllib3.connection.HTTPConnection object at 0x7fa7d6b58280>: Failed to establish a new connection: [Errno 111] Connection refused'))
During handling of the above exception, another exception occurred:
Traceback (most recent call last):
  File "/home/developer/Desktop/CIFAR-10-Paralel/Training/scripts/train.py", line 158, in <module>
    model = Train(model, optimizer, clientDataset, criterion, scheduler, epoch + 1)
  File "/home/developer/Desktop/CIFAR-10-Paralel/Training/scripts/train.py", line 32, in Train
    data, status = trainloader.__getItem__()
  File "../utils/Dataset.py", line 48, in __getItem__
    status = self.getStaus()['status']
  File "../utils/Dataset.py", line 41, in getStaus
    resp = requests.get(url=self.url + "/getStatus")
  File "/home/developer/anaconda3/envs/pytorch/lib/python3.9/site-packages/requests/api.py", line 73, in get
    return request("get", url, params=params, **kwargs)
  File "/home/developer/anaconda3/envs/pytorch/lib/python3.9/site-packages/requests/api.py", line 59, in request
    return session.request(method=method, url=url, **kwargs)
  File "/home/developer/anaconda3/envs/pytorch/lib/python3.9/site-packages/requests/sessions.py", line 587, in request
    resp = self.send(prep, **send_kwargs)
  File "/home/developer/anaconda3/envs/pytorch/lib/python3.9/site-packages/requests/sessions.py", line 701, in send
    r = adapter.send(request, **kwargs)
  File "/home/developer/anaconda3/envs/pytorch/lib/python3.9/site-packages/requests/adapters.py", line 565, in send
    raise ConnectionError(e, request=request)
requests.exceptions.ConnectionError: HTTPConnectionPool(host='127.0.0.1', port=8000): Max retries exceeded with url: /getStatus (Caused by NewConnectionError('<urllib3.connection.HTTPConnection object at 0x7fa7d6b58280>: Failed to establish a new connection: [Errno 111] Connection refused'))